<?xml version="1.0"?>
<robot xmlns:xacro="http://ros.org/wiki/xacro" name="my_robot">

  <xacro:include filename="$(find my_robot_description)/urdf/inertial_macros.xacro"/>

  <!-- Materials -->
  <material name="silver"><color rgba="0.7 0.7 0.7 1"/></material>
  <material name="dark_gray"><color rgba="0.2 0.2 0.2 1"/></material>
  <material name="black"><color rgba="0 0 0 1"/></material>

  <!-- Base Link -->
  <link name="base_link">
    <visual>
      <origin xyz="0 0 0" rpy="0 0 0"/>
      <geometry>
        <box size="0.01 0.01 0.01"/>
      </geometry>
      <material name="silver"/>
    </visual>
  </link>

  <!-- Chassis -->
  <joint name="chassis_joint" type="fixed">
    <parent link="base_link"/>
    <child link="chassis"/>
    <origin xyz="0 0 0.05"/>
  </joint>

  <link name="chassis">
    <visual>
      <origin xyz="0 0 0" rpy="0 0 0"/>
      <geometry>
        <box size="0.4 0.3 0.1"/>
      </geometry>
      <material name="silver"/>
    </visual>
    <collision>
      <origin xyz="0 0 0"/>
      <geometry>
        <box size="0.4 0.3 0.1"/>
      </geometry>
    </collision>
    <xacro:inertial_box mass="2.0" x="0.4" y="0.3" z="0.1"/>
  </link>

  <!-- Front Left Steering Assembly -->
  <joint name="front_left_steer_joint" type="revolute">
    <parent link="base_link"/>
    <child link="front_left_steer"/>
    <origin xyz="0.17 0.22 0.03" rpy="0 0 0"/>
    <axis xyz="0 0 1"/>
    <limit lower="-0.5236" upper="0.5236" effort="10.0" velocity="1.0"/>
  </joint>

  <link name="front_left_steer">
    <visual>
      <origin xyz="0 0 0" rpy="0 0 0"/>
      <geometry>
        <box size="0.02 0.02 0.02"/>
      </geometry>
      <material name="black"/>
    </visual>
    <collision>
      <origin xyz="0 0 0"/>
      <geometry>
        <box size="0.02 0.02 0.02"/>
      </geometry>
    </collision>
    <xacro:inertial_box mass="0.05" x="0.02" y="0.02" z="0.02"/>
  </link>

  <!-- Front Left Wheel -->
  <joint name="front_left_wheel_joint" type="continuous">
    <parent link="front_left_steer"/>
    <child link="front_left_wheel"/>
    <origin xyz="0 0 0" rpy="0 0 0"/>
    <axis xyz="0 1 0"/>
  </joint>

  <link name="front_left_wheel">
    <visual>
      <origin xyz="0 0 0" rpy="1.5708 0 0"/>
      <geometry>
        <cylinder radius="0.05" length="0.04"/>
      </geometry>
      <material name="dark_gray"/>
    </visual>
    <collision>
      <origin xyz="0 0 0" rpy="1.5708 0 0"/>
      <geometry>
        <cylinder radius="0.05" length="0.04"/>
      </geometry>
    </collision>
    <xacro:inertial_cylinder mass="0.1" length="0.04" radius="0.05"/>
  </link>

  <!-- Front Right Steering Assembly -->
  <joint name="front_right_steer_joint" type="revolute">
    <parent link="base_link"/>
    <child link="front_right_steer"/>
    <origin xyz="0.17 -0.22 0.03" rpy="0 0 0"/>
    <axis xyz="0 0 1"/>
    <limit lower="-0.5236" upper="0.5236" effort="10.0" velocity="1.0"/>
  </joint>


  <link name="front_right_steer">
    <visual>
      <origin xyz="0 0 0" rpy="0 0 0"/>
      <geometry>
        <box size="0.02 0.02 0.02"/>
      </geometry>
      <material name="black"/>
    </visual>
    <collision>
      <origin xyz="0 0 0"/>
      <geometry>
        <box size="0.02 0.02 0.02"/>
      </geometry>
    </collision>
    <xacro:inertial_box mass="0.05" x="0.02" y="0.02" z="0.02"/>
  </link>

  <!-- Front Right Wheel -->
  <joint name="front_right_wheel_joint" type="continuous">
    <parent link="front_right_steer"/>
    <child link="front_right_wheel"/>
    <origin xyz="0 0 0" rpy="0 0 0"/>
    <axis xyz="0 1 0"/>
  </joint>

  <link name="front_right_wheel">
    <visual>
      <origin xyz="0 0 0" rpy="1.5708 0 0"/>
      <geometry>
        <cylinder radius="0.05" length="0.04"/>
      </geometry>
      <material name="dark_gray"/>
    </visual>
    <collision>
      <origin xyz="0 0 0" rpy="1.5708 0 0"/>
      <geometry>
        <cylinder radius="0.05" length="0.04"/>
      </geometry>
    </collision>
    <xacro:inertial_cylinder mass="0.1" length="0.04" radius="0.05"/>
  </link>

  <!-- Rear Left Wheel -->
  <joint name="rear_left_wheel_joint" type="continuous">
    <parent link="base_link"/>
    <child link="rear_left_wheel"/>
    <origin xyz="-0.17 0.22 0.03" rpy="0 0 0"/>
    <axis xyz="0 1 0"/>
  </joint>

  <link name="rear_left_wheel">
    <visual>
      <origin xyz="0 0 0" rpy="1.5708 0 0"/>
      <geometry>
        <cylinder radius="0.05" length="0.04"/>
      </geometry>
      <material name="dark_gray"/>
    </visual>
    <collision>
      <origin xyz="0 0 0" rpy="1.5708 0 0"/>
      <geometry>
        <cylinder radius="0.05" length="0.04"/>
      </geometry>
    </collision>
    <xacro:inertial_cylinder mass="0.1" length="0.04" radius="0.05"/>
  </link>

  <!-- Rear Right Wheel -->
  <joint name="rear_right_wheel_joint" type="continuous">
    <parent link="base_link"/>
    <child link="rear_right_wheel"/>
    <origin xyz="-0.17 -0.22 0.03" rpy="0 0 0"/>
    <axis xyz="0 1 0"/>
  </joint>

  <link name="rear_right_wheel">
    <visual>
      <origin xyz="0 0 0" rpy="1.5708 0 0"/>
      <geometry>
        <cylinder radius="0.05" length="0.04"/>
      </geometry>
      <material name="dark_gray"/>
    </visual>
    <collision>
      <origin xyz="0 0 0" rpy="1.5708 0 0"/>
      <geometry>
        <cylinder radius="0.05" length="0.04"/>
      </geometry>
    </collision>
    <xacro:inertial_cylinder mass="0.1" length="0.04" radius="0.05"/>
  </link>

  <!-- LiDAR Sensor -->
  <joint name="lidar_joint" type="fixed">
    <parent link="chassis"/>
    <child link="lidar"/>
    <origin xyz="0 0 0.15" rpy="0 0 0"/>
  </joint>

  <link name="lidar">
    <visual>
      <origin xyz="0 0 0" rpy="0 0 0"/>
      <geometry>
        <cylinder radius="0.05" length="0.02"/>
      </geometry>
      <material name="black"/>
    </visual>
    <collision>
      <origin xyz="0 0 0"/>
      <geometry>
        <cylinder radius="0.05" length="0.02"/>
      </geometry>
    </collision>
    <xacro:inertial_cylinder mass="0.2" length="0.02" radius="0.05"/>
  </link>

  <gazebo reference="lidar">
    <sensor name="lidar_sensor" type="ray">
      <update_rate>30</update_rate>
      <ray>
        <scan>
          <horizontal>
            <samples>720</samples>
            <resolution>1</resolution>
            <min_angle>-1.5708</min_angle>
            <max_angle>1.5708</max_angle>
          </horizontal>
        </scan>
        <range>
          <min>0.1</min>
          <max>5.0</max>
          <resolution>0.01</resolution>
        </range>
      </ray>
      <plugin name="gazebo_ros_laser_controller" filename="libgazebo_ros_ray_sensor.so"/>
    </sensor>
  </gazebo>

  <!-- Camera -->
  <joint name="camera_joint" type="fixed">
    <parent link="chassis"/>
    <child link="camera"/>
    <origin xyz="0 0 0.18" rpy="0 0 0"/>
  </joint>

  <link name="camera">
    <visual>
      <origin xyz="0 0 0" rpy="0 0 0"/>
      <geometry>
        <box size="0.04 0.04 0.02"/>
      </geometry>
      <material name="black"/>
    </visual>
    <collision>
      <origin xyz="0 0 0"/>
      <geometry>
        <box size="0.04 0.04 0.02"/>
      </geometry>
    </collision>
    <xacro:inertial_box mass="0.1" x="0.04" y="0.04" z="0.02"/>
  </link>

  <gazebo reference="camera">
    <sensor name="camera_sensor" type="camera">
      <update_rate>30</update_rate>
      <camera>
        <horizontal_fov>1.3962634</horizontal_fov>
        <image>
          <width>640</width>
          <height>480</height>
          <format>R8G8B8</format>
        </image>
        <clip>
          <near>0.1</near>
          <far>100</far>
        </clip>
      </camera>
      <plugin name="gazebo_ros_camera_controller" filename="libgazebo_ros_camera.so"/>
    </sensor>
  </gazebo>

  <!-- Differential Drive Plugin -->
  <gazebo>
    <plugin name="diff_drive_controller" filename="libgazebo_ros_diff_drive.so">
      <ros>
        <namespace>/</namespace>
        <remapping>cmd_vel:=/cmd_vel</remapping>
      </ros>

      <left_joint>rear_left_wheel_joint</left_joint>
      <right_joint>rear_right_wheel_joint</right_joint>

      <wheel_separation>0.3</wheel_separation>
      <wheel_diameter>0.1</wheel_diameter>

      <command_topic>/cmd_vel</command_topic>
      <odometry_topic>/odom</odometry_topic>
      <odometry_frame>odom</odometry_frame>
      <robot_base_frame>base_link</robot_base_frame>

      <publish_odom>true</publish_odom>
      <publish_odom_tf>true</publish_odom_tf>

      <!-- Smoothness controls -->
      <update_rate>50.0</update_rate>
      <max_wheel_torque>5.0</max_wheel_torque>
      <max_wheel_acceleration>1.5</max_wheel_acceleration> <!-- helps ramp up/down -->
    </plugin>
  </gazebo>


  <!-- Transmissions for hardware interface -->
  <transmission name="rear_left_wheel_trans">
    <type>transmission_interface/SimpleTransmission</type>
    <joint name="rear_left_wheel_joint">
      <hardwareInterface>hardware_interface/VelocityJointInterface</hardwareInterface>
    </joint>
    <actuator name="motor_rear_left">
      <hardwareInterface>hardware_interface/VelocityJointInterface</hardwareInterface>
      <mechanicalReduction>1</mechanicalReduction>
    </actuator>
  </transmission>

  <transmission name="rear_right_wheel_trans">
    <type>transmission_interface/SimpleTransmission</type>
    <joint name="rear_right_wheel_joint">
      <hardwareInterface>hardware_interface/VelocityJointInterface</hardwareInterface>
    </joint>
    <actuator name="motor_rear_right">
      <hardwareInterface>hardware_interface/VelocityJointInterface</hardwareInterface>
      <mechanicalReduction>1</mechanicalReduction>
    </actuator>
  </transmission>

  <transmission name="front_left_steering_trans">
    <type>transmission_interface/SimpleTransmission</type>
    <joint name="front_left_steer_joint">
      <hardwareInterface>hardware_interface/PositionJointInterface</hardwareInterface>
    </joint>
    <actuator name="steering_motor_left">
      <hardwareInterface>hardware_interface/PositionJointInterface</hardwareInterface>
      <mechanicalReduction>1</mechanicalReduction>
    </actuator>
  </transmission>

  <transmission name="front_right_steering_trans">
    <type>transmission_interface/SimpleTransmission</type>
    <joint name="front_right_steer_joint">
      <hardwareInterface>hardware_interface/PositionJointInterface</hardwareInterface>
    </joint>
    <actuator name="steering_motor_right">
      <hardwareInterface>hardware_interface/PositionJointInterface</hardwareInterface>
      <mechanicalReduction>1</mechanicalReduction>
    </actuator>
  </transmission>

</robot>